2024-08-16 20:55:02,077 - 'NeuralNetwork' object has no attribute 'output_activation'
Traceback (most recent call last):
  File "/var/home/vita/NNoptimization/PYTORCH/.venv/lib64/python3.12/site-packages/pygad/pygad.py", line 1708, in cal_pop_fitness
    fitness = self.fitness_func(self, sol, sol_idx)
              ^^^^^^^^^^^^^^^^^^^^^^^^^^^^^^^^^^^^^
  File "/var/home/vita/NNoptimization/PYTORCH/ga2.py", line 300, in fitness_func
    solution_nn.train_model(train_loader, val_loader)
  File "/var/home/vita/NNoptimization/PYTORCH/nn2.py", line 99, in train_model
    outputs = self(batch_data)
              ^^^^^^^^^^^^^^^^
  File "/var/home/vita/NNoptimization/PYTORCH/.venv/lib64/python3.12/site-packages/torch/nn/modules/module.py", line 1553, in _wrapped_call_impl
    return self._call_impl(*args, **kwargs)
           ^^^^^^^^^^^^^^^^^^^^^^^^^^^^^^^^
  File "/var/home/vita/NNoptimization/PYTORCH/.venv/lib64/python3.12/site-packages/torch/nn/modules/module.py", line 1562, in _call_impl
    return forward_call(*args, **kwargs)
           ^^^^^^^^^^^^^^^^^^^^^^^^^^^^^
  File "/var/home/vita/NNoptimization/PYTORCH/nn2.py", line 87, in forward
    return self.output_activation(x)
           ^^^^^^^^^^^^^^^^^^^^^^
  File "/var/home/vita/NNoptimization/PYTORCH/.venv/lib64/python3.12/site-packages/torch/nn/modules/module.py", line 1729, in __getattr__
    raise AttributeError(f"'{type(self).__name__}' object has no attribute '{name}'")
AttributeError: 'NeuralNetwork' object has no attribute 'output_activation'
2024-08-16 20:55:02,119 - 'NeuralNetwork' object has no attribute 'output_activation'
Traceback (most recent call last):
  File "/var/home/vita/NNoptimization/PYTORCH/.venv/lib64/python3.12/site-packages/pygad/pygad.py", line 1914, in run
    self.last_generation_fitness = self.cal_pop_fitness()
                                   ^^^^^^^^^^^^^^^^^^^^^^
  File "/var/home/vita/NNoptimization/PYTORCH/.venv/lib64/python3.12/site-packages/pygad/pygad.py", line 1871, in cal_pop_fitness
    raise ex
  File "/var/home/vita/NNoptimization/PYTORCH/.venv/lib64/python3.12/site-packages/pygad/pygad.py", line 1708, in cal_pop_fitness
    fitness = self.fitness_func(self, sol, sol_idx)
              ^^^^^^^^^^^^^^^^^^^^^^^^^^^^^^^^^^^^^
  File "/var/home/vita/NNoptimization/PYTORCH/ga2.py", line 300, in fitness_func
    solution_nn.train_model(train_loader, val_loader)
  File "/var/home/vita/NNoptimization/PYTORCH/nn2.py", line 99, in train_model
    outputs = self(batch_data)
              ^^^^^^^^^^^^^^^^
  File "/var/home/vita/NNoptimization/PYTORCH/.venv/lib64/python3.12/site-packages/torch/nn/modules/module.py", line 1553, in _wrapped_call_impl
    return self._call_impl(*args, **kwargs)
           ^^^^^^^^^^^^^^^^^^^^^^^^^^^^^^^^
  File "/var/home/vita/NNoptimization/PYTORCH/.venv/lib64/python3.12/site-packages/torch/nn/modules/module.py", line 1562, in _call_impl
    return forward_call(*args, **kwargs)
           ^^^^^^^^^^^^^^^^^^^^^^^^^^^^^
  File "/var/home/vita/NNoptimization/PYTORCH/nn2.py", line 87, in forward
    return self.output_activation(x)
           ^^^^^^^^^^^^^^^^^^^^^^
  File "/var/home/vita/NNoptimization/PYTORCH/.venv/lib64/python3.12/site-packages/torch/nn/modules/module.py", line 1729, in __getattr__
    raise AttributeError(f"'{type(self).__name__}' object has no attribute '{name}'")
AttributeError: 'NeuralNetwork' object has no attribute 'output_activation'
2024-08-16 21:20:52,718 - 'NeuralNetwork' object has no attribute 'output_activation'
Traceback (most recent call last):
  File "/var/home/vita/NNoptimization/PYTORCH/.venv/lib64/python3.12/site-packages/pygad/pygad.py", line 1708, in cal_pop_fitness
    fitness = self.fitness_func(self, sol, sol_idx)
              ^^^^^^^^^^^^^^^^^^^^^^^^^^^^^^^^^^^^^
  File "/var/home/vita/NNoptimization/PYTORCH/ga2.py", line 300, in fitness_func
    solution_nn.train_model(train_loader, val_loader)
  File "/var/home/vita/NNoptimization/PYTORCH/nn2.py", line 99, in train_model
    outputs = self(batch_data)
              ^^^^^^^^^^^^^^^^
  File "/var/home/vita/NNoptimization/PYTORCH/.venv/lib64/python3.12/site-packages/torch/nn/modules/module.py", line 1553, in _wrapped_call_impl
    return self._call_impl(*args, **kwargs)
           ^^^^^^^^^^^^^^^^^^^^^^^^^^^^^^^^
  File "/var/home/vita/NNoptimization/PYTORCH/.venv/lib64/python3.12/site-packages/torch/nn/modules/module.py", line 1562, in _call_impl
    return forward_call(*args, **kwargs)
           ^^^^^^^^^^^^^^^^^^^^^^^^^^^^^
  File "/var/home/vita/NNoptimization/PYTORCH/nn2.py", line 87, in forward
    return self.output_activation(x)
           ^^^^^^^^^^^^^^^^^^^^^^
  File "/var/home/vita/NNoptimization/PYTORCH/.venv/lib64/python3.12/site-packages/torch/nn/modules/module.py", line 1729, in __getattr__
    raise AttributeError(f"'{type(self).__name__}' object has no attribute '{name}'")
AttributeError: 'NeuralNetwork' object has no attribute 'output_activation'
2024-08-16 21:20:52,761 - 'NeuralNetwork' object has no attribute 'output_activation'
Traceback (most recent call last):
  File "/var/home/vita/NNoptimization/PYTORCH/.venv/lib64/python3.12/site-packages/pygad/pygad.py", line 1914, in run
    self.last_generation_fitness = self.cal_pop_fitness()
                                   ^^^^^^^^^^^^^^^^^^^^^^
  File "/var/home/vita/NNoptimization/PYTORCH/.venv/lib64/python3.12/site-packages/pygad/pygad.py", line 1871, in cal_pop_fitness
    raise ex
  File "/var/home/vita/NNoptimization/PYTORCH/.venv/lib64/python3.12/site-packages/pygad/pygad.py", line 1708, in cal_pop_fitness
    fitness = self.fitness_func(self, sol, sol_idx)
              ^^^^^^^^^^^^^^^^^^^^^^^^^^^^^^^^^^^^^
  File "/var/home/vita/NNoptimization/PYTORCH/ga2.py", line 300, in fitness_func
    solution_nn.train_model(train_loader, val_loader)
  File "/var/home/vita/NNoptimization/PYTORCH/nn2.py", line 99, in train_model
    outputs = self(batch_data)
              ^^^^^^^^^^^^^^^^
  File "/var/home/vita/NNoptimization/PYTORCH/.venv/lib64/python3.12/site-packages/torch/nn/modules/module.py", line 1553, in _wrapped_call_impl
    return self._call_impl(*args, **kwargs)
           ^^^^^^^^^^^^^^^^^^^^^^^^^^^^^^^^
  File "/var/home/vita/NNoptimization/PYTORCH/.venv/lib64/python3.12/site-packages/torch/nn/modules/module.py", line 1562, in _call_impl
    return forward_call(*args, **kwargs)
           ^^^^^^^^^^^^^^^^^^^^^^^^^^^^^
  File "/var/home/vita/NNoptimization/PYTORCH/nn2.py", line 87, in forward
    return self.output_activation(x)
           ^^^^^^^^^^^^^^^^^^^^^^
  File "/var/home/vita/NNoptimization/PYTORCH/.venv/lib64/python3.12/site-packages/torch/nn/modules/module.py", line 1729, in __getattr__
    raise AttributeError(f"'{type(self).__name__}' object has no attribute '{name}'")
AttributeError: 'NeuralNetwork' object has no attribute 'output_activation'
2024-08-16 22:09:41,465 - 'NeuralNetwork' object has no attribute 'output_activation'
Traceback (most recent call last):
  File "/var/home/vita/NNoptimization/PYTORCH/.venv/lib64/python3.12/site-packages/pygad/pygad.py", line 1708, in cal_pop_fitness
    fitness = self.fitness_func(self, sol, sol_idx)
              ^^^^^^^^^^^^^^^^^^^^^^^^^^^^^^^^^^^^^
  File "/var/home/vita/NNoptimization/PYTORCH/ga2.py", line 300, in fitness_func
    solution_nn.train_model(train_loader, val_loader)
  File "/var/home/vita/NNoptimization/PYTORCH/nn2.py", line 99, in train_model
    outputs = self(batch_data)
              ^^^^^^^^^^^^^^^^
  File "/var/home/vita/NNoptimization/PYTORCH/.venv/lib64/python3.12/site-packages/torch/nn/modules/module.py", line 1553, in _wrapped_call_impl
    return self._call_impl(*args, **kwargs)
           ^^^^^^^^^^^^^^^^^^^^^^^^^^^^^^^^
  File "/var/home/vita/NNoptimization/PYTORCH/.venv/lib64/python3.12/site-packages/torch/nn/modules/module.py", line 1562, in _call_impl
    return forward_call(*args, **kwargs)
           ^^^^^^^^^^^^^^^^^^^^^^^^^^^^^
  File "/var/home/vita/NNoptimization/PYTORCH/nn2.py", line 87, in forward
    return self.output_activation(x)
           ^^^^^^^^^^^^^^^^^^^^^^
  File "/var/home/vita/NNoptimization/PYTORCH/.venv/lib64/python3.12/site-packages/torch/nn/modules/module.py", line 1729, in __getattr__
    raise AttributeError(f"'{type(self).__name__}' object has no attribute '{name}'")
AttributeError: 'NeuralNetwork' object has no attribute 'output_activation'
2024-08-16 22:09:41,507 - 'NeuralNetwork' object has no attribute 'output_activation'
Traceback (most recent call last):
  File "/var/home/vita/NNoptimization/PYTORCH/.venv/lib64/python3.12/site-packages/pygad/pygad.py", line 1914, in run
    self.last_generation_fitness = self.cal_pop_fitness()
                                   ^^^^^^^^^^^^^^^^^^^^^^
  File "/var/home/vita/NNoptimization/PYTORCH/.venv/lib64/python3.12/site-packages/pygad/pygad.py", line 1871, in cal_pop_fitness
    raise ex
  File "/var/home/vita/NNoptimization/PYTORCH/.venv/lib64/python3.12/site-packages/pygad/pygad.py", line 1708, in cal_pop_fitness
    fitness = self.fitness_func(self, sol, sol_idx)
              ^^^^^^^^^^^^^^^^^^^^^^^^^^^^^^^^^^^^^
  File "/var/home/vita/NNoptimization/PYTORCH/ga2.py", line 300, in fitness_func
    solution_nn.train_model(train_loader, val_loader)
  File "/var/home/vita/NNoptimization/PYTORCH/nn2.py", line 99, in train_model
    outputs = self(batch_data)
              ^^^^^^^^^^^^^^^^
  File "/var/home/vita/NNoptimization/PYTORCH/.venv/lib64/python3.12/site-packages/torch/nn/modules/module.py", line 1553, in _wrapped_call_impl
    return self._call_impl(*args, **kwargs)
           ^^^^^^^^^^^^^^^^^^^^^^^^^^^^^^^^
  File "/var/home/vita/NNoptimization/PYTORCH/.venv/lib64/python3.12/site-packages/torch/nn/modules/module.py", line 1562, in _call_impl
    return forward_call(*args, **kwargs)
           ^^^^^^^^^^^^^^^^^^^^^^^^^^^^^
  File "/var/home/vita/NNoptimization/PYTORCH/nn2.py", line 87, in forward
    return self.output_activation(x)
           ^^^^^^^^^^^^^^^^^^^^^^
  File "/var/home/vita/NNoptimization/PYTORCH/.venv/lib64/python3.12/site-packages/torch/nn/modules/module.py", line 1729, in __getattr__
    raise AttributeError(f"'{type(self).__name__}' object has no attribute '{name}'")
AttributeError: 'NeuralNetwork' object has no attribute 'output_activation'
2024-08-16 22:12:13,279 - 'NeuralNetwork' object has no attribute 'output_activation'
Traceback (most recent call last):
  File "/var/home/vita/NNoptimization/PYTORCH/.venv/lib64/python3.12/site-packages/pygad/pygad.py", line 1708, in cal_pop_fitness
    fitness = self.fitness_func(self, sol, sol_idx)
              ^^^^^^^^^^^^^^^^^^^^^^^^^^^^^^^^^^^^^
  File "/var/home/vita/NNoptimization/PYTORCH/ga2.py", line 300, in fitness_func
    solution_nn.train_model(train_loader, val_loader)
  File "/var/home/vita/NNoptimization/PYTORCH/nn2.py", line 99, in train_model
    outputs = self(batch_data)
              ^^^^^^^^^^^^^^^^
  File "/var/home/vita/NNoptimization/PYTORCH/.venv/lib64/python3.12/site-packages/torch/nn/modules/module.py", line 1553, in _wrapped_call_impl
    return self._call_impl(*args, **kwargs)
           ^^^^^^^^^^^^^^^^^^^^^^^^^^^^^^^^
  File "/var/home/vita/NNoptimization/PYTORCH/.venv/lib64/python3.12/site-packages/torch/nn/modules/module.py", line 1562, in _call_impl
    return forward_call(*args, **kwargs)
           ^^^^^^^^^^^^^^^^^^^^^^^^^^^^^
  File "/var/home/vita/NNoptimization/PYTORCH/nn2.py", line 87, in forward
    return self.output_activation(x)
           ^^^^^^^^^^^^^^^^^^^^^^
  File "/var/home/vita/NNoptimization/PYTORCH/.venv/lib64/python3.12/site-packages/torch/nn/modules/module.py", line 1729, in __getattr__
    raise AttributeError(f"'{type(self).__name__}' object has no attribute '{name}'")
AttributeError: 'NeuralNetwork' object has no attribute 'output_activation'
2024-08-16 22:12:13,325 - 'NeuralNetwork' object has no attribute 'output_activation'
Traceback (most recent call last):
  File "/var/home/vita/NNoptimization/PYTORCH/.venv/lib64/python3.12/site-packages/pygad/pygad.py", line 1914, in run
    self.last_generation_fitness = self.cal_pop_fitness()
                                   ^^^^^^^^^^^^^^^^^^^^^^
  File "/var/home/vita/NNoptimization/PYTORCH/.venv/lib64/python3.12/site-packages/pygad/pygad.py", line 1871, in cal_pop_fitness
    raise ex
  File "/var/home/vita/NNoptimization/PYTORCH/.venv/lib64/python3.12/site-packages/pygad/pygad.py", line 1708, in cal_pop_fitness
    fitness = self.fitness_func(self, sol, sol_idx)
              ^^^^^^^^^^^^^^^^^^^^^^^^^^^^^^^^^^^^^
  File "/var/home/vita/NNoptimization/PYTORCH/ga2.py", line 300, in fitness_func
    solution_nn.train_model(train_loader, val_loader)
  File "/var/home/vita/NNoptimization/PYTORCH/nn2.py", line 99, in train_model
    outputs = self(batch_data)
              ^^^^^^^^^^^^^^^^
  File "/var/home/vita/NNoptimization/PYTORCH/.venv/lib64/python3.12/site-packages/torch/nn/modules/module.py", line 1553, in _wrapped_call_impl
    return self._call_impl(*args, **kwargs)
           ^^^^^^^^^^^^^^^^^^^^^^^^^^^^^^^^
  File "/var/home/vita/NNoptimization/PYTORCH/.venv/lib64/python3.12/site-packages/torch/nn/modules/module.py", line 1562, in _call_impl
    return forward_call(*args, **kwargs)
           ^^^^^^^^^^^^^^^^^^^^^^^^^^^^^
  File "/var/home/vita/NNoptimization/PYTORCH/nn2.py", line 87, in forward
    return self.output_activation(x)
           ^^^^^^^^^^^^^^^^^^^^^^
  File "/var/home/vita/NNoptimization/PYTORCH/.venv/lib64/python3.12/site-packages/torch/nn/modules/module.py", line 1729, in __getattr__
    raise AttributeError(f"'{type(self).__name__}' object has no attribute '{name}'")
AttributeError: 'NeuralNetwork' object has no attribute 'output_activation'
